<?xml version="1.0"?>
<robot xmlns:xacro="http://www.ros.org/wiki/xacro"  name="robot">

    <!-- Example link-->


      <!-- color -->
    <material name="black">
    <color rgba="0.0 0.0 0.0 1.0"/>
  </material>

  <material name="blue">
    <color rgba="0.0 0.0 0.8 1.0"/>
  </material>

  <material name="orange">
    <color rgba="${255/255} ${108/255} ${10/255} 1.0"/>
  </material>

   <material name="white">
    <color rgba="1 1 1 1"/>
  </material>
<!-- BASE link-->
  <link name="base_link"> 
  </link> 

  
  <!-- chassis link -->
  <joint name="chassis_joint" type="fixed"> 
    <parent link="base_link"/>
    <child link="chassis"/> 
    <origin xyz = "-0.1 0 0"/> 
  </joint>


  <link name="chassis"> 
    <visual>
        <origin xyz="0.15 0 0.075"/> 
        <geometry>
            <box size= "0.3 0.3 0.15"/> 
        </geometry>
        <material  name="white"/> 
    </visual> 
</link>


  <!-- LEFT WHEEL lINK -->
 <joint name="left_wheel_joint" type="continuous">
    <parent link="base_link"/>
    <child  link= "left_wheel"/> 
    <origin xyz="0 0.175 0" rpy="-${pi/2} 0 0"/>
    <axis xyz="0 0 1"/>
 </joint> 

 <link name="left_wheel"> 
    <visual>
        <geometry>
            <cylinder radius="0.05" length="0.04"/>
        </geometry>
        <material name="blue"/>          
    </visual>
</link>
    
 <joint name="right_wheel_joint" type="continuous">
    <parent link="base_link"/>
    <child  link= "right_wheel"/> 
    <origin xyz="0 -0.175 0" rpy="-${pi/2} 0 0"/>
    <axis xyz="0 0 -1"/>
 </joint> 

 <link name="right_wheel"> 
    <visual>
        <geometry>
            <cylinder radius="0.05" length="0.04"/>
        </geometry>
        <material name="blue"/>         
    </visual>
</link> 

 <!--CASTER WHEEL lINK -->

 <joint name="caster_wheel_joint" type="fixed">
    <origin xyz="0.24 0 0" rpy="0.0 0.0 0.0"/>
    <parent link="chassis"/>
    <child link="caster_wheel"/>
    <axis xyz="0.0 0.0 0.0"/>
    <limit lower="0.0" upper="0.0" effort="0.0" velocity="0.0"/>
 </joint>   

 <link name="caster_wheel">
    <visual>
        <geometry>
            <sphere radius="0.05"/>
        </geometry>
        <material name="black"/>
    </visual>
 </link>



</robot>