<sdf version='1.7'>
  <world name='default'>
    <light name='sun' type='directional'>
      <cast_shadows>1</cast_shadows>
      <pose>0 0 10 0 -0 0</pose>
      <diffuse>0.8 0.8 0.8 1</diffuse>
      <specular>0.2 0.2 0.2 1</specular>
      <attenuation>
        <range>1000</range>
        <constant>0.9</constant>
        <linear>0.01</linear>
        <quadratic>0.001</quadratic>
      </attenuation>
      <direction>-0.5 0.1 -0.9</direction>
      <spot>
        <inner_angle>0</inner_angle>
        <outer_angle>0</outer_angle>
        <falloff>0</falloff>
      </spot>
    </light>
    <model name='ground_plane'>
      <static>1</static>
      <link name='link'>
        <collision name='collision'>
          <geometry>
            <plane>
              <normal>0 0 1</normal>
              <size>100 100</size>
            </plane>
          </geometry>
          <surface>
            <contact>
              <collide_bitmask>65535</collide_bitmask>
              <ode/>
            </contact>
            <friction>
              <ode>
                <mu>100</mu>
                <mu2>50</mu2>
              </ode>
              <torsional>
                <ode/>
              </torsional>
            </friction>
            <bounce/>
          </surface>
          <max_contacts>10</max_contacts>
        </collision>
        <visual name='visual'>
          <cast_shadows>0</cast_shadows>
          <geometry>
            <plane>
              <normal>0 0 1</normal>
              <size>100 100</size>
            </plane>
          </geometry>
          <material>
            <script>
              <uri>file://media/materials/scripts/gazebo.material</uri>
              <name>Gazebo/Grey</name>
            </script>
          </material>
        </visual>
        <self_collide>0</self_collide>
        <enable_wind>0</enable_wind>
        <kinematic>0</kinematic>
      </link>
    </model>
    <gravity>0 0 -9.8</gravity>
    <magnetic_field>6e-06 2.3e-05 -4.2e-05</magnetic_field>
    <atmosphere type='adiabatic'/>
    <physics type='ode'>
      <max_step_size>0.001</max_step_size>
      <real_time_factor>1</real_time_factor>
      <real_time_update_rate>1000</real_time_update_rate>
    </physics>
    <scene>
      <ambient>0.4 0.4 0.4 1</ambient>
      <background>0.7 0.7 0.7 1</background>
      <shadows>1</shadows>
    </scene>
    <audio>
      <device>default</device>
    </audio>
    <wind/>
    <spherical_coordinates>
      <surface_model>EARTH_WGS84</surface_model>
      <latitude_deg>0</latitude_deg>
      <longitude_deg>0</longitude_deg>
      <elevation>0</elevation>
      <heading_deg>0</heading_deg>
    </spherical_coordinates>
    <state world_name='default'>
      <sim_time>80 989000000</sim_time>
      <real_time>52 48785561</real_time>
      <wall_time>1687947013 886277853</wall_time>
      <iterations>32196</iterations>
      <model name='bot'>
        <pose>0 -0 0 0 -0 0</pose>
        <scale>1 1 1</scale>
        <link name='base_link'>
          <pose>0 -0 0 0 -0 0</pose>
          <velocity>0 -0 -0 -1e-06 -0 -0</velocity>
          <acceleration>2e-05 -3.8e-05 3.9e-05 0.001745 0.001359 1.2e-05</acceleration>
          <wrench>0.000405 -0.000766 0.000787 0 -0 0</wrench>
        </link>
        <link name='gripper_link_1'>
          <pose>0.298567 -0.735899 0.363194 2.90403 -1.02457 -1.09467</pose>
          <velocity>0.062419 -0.006191 0.017984 1.53194 1.29394 1.70507</velocity>
          <acceleration>-0.314165 0.52877 -0.980332 -1.41596 -0.732619 -1.55692</acceleration>
          <wrench>-0.062833 0.105754 -0.196066 0 -0 0</wrench>
        </link>
        <link name='gripper_link_2'>
          <pose>0.28428 -0.708194 0.311918 2.90403 -1.02457 -1.09467</pose>
          <velocity>-0.489759 -0.155954 0.08584 1.53193 1.29395 1.70507</velocity>
          <acceleration>1.50841 -2.12547 4.03064 -1.41625 -0.723133 -1.56224</acceleration>
          <wrench>0.301681 -0.425093 0.806128 0 -0 0</wrench>
        </link>
        <link name='link_1'>
          <pose>0 -0 0.15 0 -0 0.199999</pose>
          <velocity>0 -0 -0 -2e-06 -1e-06 -0.001086</velocity>
          <acceleration>0.000252 -0.00029 3.8e-05 0.000901 0.001002 -1.08609</acceleration>
          <wrench>0.001259 -0.001452 0.000189 0 -0 0</wrench>
        </link>
        <link name='link_1_endlink'>
          <pose>-0.049003 -0.009934 0.54 -0.039057 1.57079 0.160942</pose>
          <velocity>-3e-05 0.000145 -0 -2e-06 -0 -0.001086</velocity>
          <acceleration>-0.002891 0.00419 0.000308 0.006856 0.000669 0.005168</acceleration>
          <wrench>-0.004818 0.006984 0.000513 0 -0 0</wrench>
        </link>
        <link name='link_2'>
          <pose>0.083306 0.016887 0.55 1.60003 -1e-06 0.199999</pose>
          <velocity>0.000325 -0.00024 0.007119 0.02792 0.005659 -0.001086</velocity>
          <acceleration>-0.28857 0.059115 -7.11962 2.79585 -0.653166 -0.042651</acceleration>
          <wrench>-0.865709 0.177345 -21.3589 0 -0 0</wrench>
        </link>
        <link name='link_2_endlink'>
          <pose>0.146309 -0.470095 0.535672 1.5708 -0.02922 1.77079</pose>
          <velocity>-0.000606 0.000305 -0.013949 0.027926 0.00566 -0.001085</velocity>
          <acceleration>-0.007411 0.002067 0.04229 0.197264 0.032855 0.014314</acceleration>
          <wrench>-0.007411 0.002067 0.04229 0 -0 0</wrench>
        </link>
        <link name='link_3'>
          <pose>0.234451 -0.42673 0.536409 2.10004 -2e-06 0.199999</pose>
          <velocity>0.000165 -0.00265 -0.008351 0.037017 0.007502 -0.001086</velocity>
          <acceleration>-1.24596 2.89979 -18.1332 -0.588375 0.772171 -0.326223</acceleration>
          <wrench>-3.73789 8.69936 -54.3997 0 -0 0</wrench>
        </link>
        <link name='link_4'>
          <pose>0.285898 -0.680525 0.384945 2.90403 -1.02457 -1.09467</pose>
          <velocity>-0.061143 -0.07428 0.09085 1.53193 1.29394 1.70507</velocity>
          <acceleration>0.028496 -0.072678 0.134834 -1.58458 -0.658635 0.127205</acceleration>
          <wrench>0.028525 -0.07275 0.134968 0 -0 0</wrench>
        </link>
      </model>
      <model name='ground_plane'>
        <pose>0 0 0 0 -0 0</pose>
        <scale>1 1 1</scale>
        <link name='link'>
          <pose>0 0 0 0 -0 0</pose>
          <velocity>0 0 0 0 -0 0</velocity>
          <acceleration>0 0 0 0 -0 0</acceleration>
          <wrench>0 0 0 0 -0 0</wrench>
        </link>
      </model>
      <model name='unit_sphere'>
        <pose>-63.3646 -159.673 0.5 0 -0 0</pose>
        <scale>1 1 1</scale>
        <link name='link'>
          <pose>-63.4823 -160.739 0.5 0 -0 0</pose>
          <velocity>0 0 0 0 -0 0</velocity>
          <acceleration>0 0 0 0 -0 0</acceleration>
          <wrench>0 0 0 0 -0 0</wrench>
        </link>
      </model>
      <model name='unit_sphere_0'>
        <pose>0.872484 -0.532161 0.5 0 -0 0</pose>
        <scale>1 1 1</scale>
        <link name='link'>
          <pose>0.602162 -0.604432 0.400825 0 -0 0</pose>
          <velocity>0 0 0 0 -0 0</velocity>
          <acceleration>0 0 0 0 -0 0</acceleration>
          <wrench>0 0 0 0 -0 0</wrench>
        </link>
      </model>
      <light name='sun'>
        <pose>0 0 10 0 -0 0</pose>
      </light>
    </state>
    <gui fullscreen='0'>
      <camera name='user_camera'>
        <pose>0.545859 0.673499 1.59078 0 0.837022 -1.70426</pose>
        <view_controller>orbit</view_controller>
        <projection_type>perspective</projection_type>
      </camera>
    </gui>
    <model name='bot'>
      <joint name='world_joint' type='fixed'>
        <pose relative_to='__model__'>0 0 0 0 -0 0</pose>
        <parent>world</parent>
        <child>base_link</child>
      </joint>
      <link name='base_link'>
        <pose relative_to='world_joint'>0 0 0 0 -0 0</pose>
        <inertial>
          <pose>0 0 0.075 0 -0 0</pose>
          <mass>20</mass>
          <inertia>
            <ixx>0.104167</ixx>
            <ixy>0</ixy>
            <ixz>0</ixz>
            <iyy>0.104167</iyy>
            <iyz>0</iyz>
            <izz>0.133333</izz>
          </inertia>
        </inertial>
        <collision name='base_link_collision'>
          <pose>0 0 0.075 0 -0 0</pose>
          <geometry>
            <cylinder>
              <length>0.15</length>
              <radius>0.1</radius>
            </cylinder>
          </geometry>
          <surface>
            <contact>
              <ode/>
            </contact>
            <friction>
              <ode/>
              <torsional>
                <ode/>
              </torsional>
            </friction>
            <bounce/>
          </surface>
          <max_contacts>10</max_contacts>
        </collision>
        <visual name='base_link_visual'>
          <pose>0 0 0.075 0 -0 0</pose>
          <geometry>
            <cylinder>
              <length>0.15</length>
              <radius>0.1</radius>
            </cylinder>
          </geometry>
          <material>
            <ambient>0.589 0.793 1 1</ambient>
            <diffuse>0.566667 0.566667 0.566667 1</diffuse>
            <specular>0.6 0.6 0.6 1</specular>
          </material>
        </visual>
        <self_collide>0</self_collide>
        <enable_wind>0</enable_wind>
        <kinematic>0</kinematic>
      </link>
      <joint name='joint_1' type='revolute'>
        <pose relative_to='base_link'>0 0 0.15 0 -0 0</pose>
        <parent>base_link</parent>
        <child>link_1</child>
        <axis>
          <xyz>0 0 1</xyz>
          <limit>
            <lower>0</lower>
            <upper>6.28318</upper>
            <effort>300</effort>
            <velocity>1</velocity>
          </limit>
          <dynamics>
            <spring_reference>0</spring_reference>
            <spring_stiffness>0</spring_stiffness>
          </dynamics>
        </axis>
      </joint>
      <link name='link_1'>
        <pose relative_to='joint_1'>0 0 0 0 -0 0</pose>
        <inertial>
          <pose>0 0 0.2 0 -0 0</pose>
          <mass>5</mass>
          <inertia>
            <ixx>0.0708333</ixx>
            <ixy>0</ixy>
            <ixz>0</ixz>
            <iyy>0.0708333</iyy>
            <iyz>0</iyz>
            <izz>0.00833333</izz>
          </inertia>
        </inertial>
        <collision name='link_1_collision'>
          <pose>0 0 0.2 0 -0 0</pose>
          <geometry>
            <cylinder>
              <length>0.4</length>
              <radius>0.05</radius>
            </cylinder>
          </geometry>
          <surface>
            <contact>
              <ode/>
            </contact>
            <friction>
              <ode/>
              <torsional>
                <ode/>
              </torsional>
            </friction>
            <bounce/>
          </surface>
          <max_contacts>10</max_contacts>
        </collision>
        <visual name='link_1_visual'>
          <pose>0 0 0.2 0 -0 0</pose>
          <geometry>
            <cylinder>
              <length>0.4</length>
              <radius>0.05</radius>
            </cylinder>
          </geometry>
          <material>
            <ambient>0.5 0.5 0.5 1</ambient>
            <diffuse>0.566667 0.566667 0.566667 1</diffuse>
            <specular>0.6 0.6 0.6 1</specular>
          </material>
        </visual>
        <self_collide>0</self_collide>
        <enable_wind>0</enable_wind>
        <kinematic>0</kinematic>
      </link>
      <joint name='joint_2' type='revolute'>
        <pose relative_to='link_1'>0.085 0 0.4 0 -0 0</pose>
        <parent>link_1</parent>
        <child>link_2</child>
        <axis>
          <xyz>1 0 0</xyz>
          <limit>
            <lower>-3.14159</lower>
            <upper>6.28318</upper>
            <effort>300</effort>
            <velocity>1</velocity>
          </limit>
          <dynamics>
            <spring_reference>0</spring_reference>
            <spring_stiffness>0</spring_stiffness>
          </dynamics>
        </axis>
      </joint>
      <link name='link_2'>
        <pose relative_to='joint_2'>0 0 0 0 -0 0</pose>
        <inertial>
          <pose>0 0 0.25 0 -0 0</pose>
          <mass>3</mass>
          <inertia>
            <ixx>0.063725</ixx>
            <ixy>0</ixy>
            <ixz>0</ixz>
            <iyy>0.063725</iyy>
            <iyz>0</iyz>
            <izz>0.00245</izz>
          </inertia>
        </inertial>
        <collision name='link_2_collision'>
          <pose>0 0 0.25 0 -0 0</pose>
          <geometry>
            <cylinder>
              <length>0.5</length>
              <radius>0.035</radius>
            </cylinder>
          </geometry>
          <surface>
            <contact>
              <ode/>
            </contact>
            <friction>
              <ode/>
              <torsional>
                <ode/>
              </torsional>
            </friction>
            <bounce/>
          </surface>
          <max_contacts>10</max_contacts>
        </collision>
        <visual name='link_2_visual'>
          <pose>0 0 0.25 0 -0 0</pose>
          <geometry>
            <cylinder>
              <length>0.5</length>
              <radius>0.035</radius>
            </cylinder>
          </geometry>
          <material>
            <ambient>0.5 0.5 0.5 1</ambient>
            <diffuse>0.566667 0.566667 0.566667 1</diffuse>
            <specular>0.6 0.6 0.6 1</specular>
          </material>
        </visual>
        <self_collide>0</self_collide>
        <enable_wind>0</enable_wind>
        <kinematic>0</kinematic>
      </link>
      <joint name='joint_3' type='revolute'>
        <pose relative_to='link_2'>0.06 0 0.465 0 -0 0</pose>
        <parent>link_2</parent>
        <child>link_3</child>
        <axis>
          <xyz>1 0 0</xyz>
          <limit>
            <lower>-3.14159</lower>
            <upper>6.28318</upper>
            <effort>300</effort>
            <velocity>1</velocity>
          </limit>
          <dynamics>
            <spring_reference>0</spring_reference>
            <spring_stiffness>0</spring_stiffness>
          </dynamics>
        </axis>
      </joint>
      <link name='link_3'>
        <pose relative_to='joint_3'>0 0 0 0 -0 0</pose>
        <inertial>
          <pose>0 0 0.15 0 -0 0</pose>
          <mass>3</mass>
          <inertia>
            <ixx>0.023125</ixx>
            <ixy>0</ixy>
            <ixz>0</ixz>
            <iyy>0.023125</iyy>
            <iyz>0</iyz>
            <izz>0.00125</izz>
          </inertia>
        </inertial>
        <collision name='link_3_collision'>
          <pose>0 0 0.15 0 -0 0</pose>
          <geometry>
            <cylinder>
              <length>0.3</length>
              <radius>0.025</radius>
            </cylinder>
          </geometry>
          <surface>
            <contact>
              <ode/>
            </contact>
            <friction>
              <ode/>
              <torsional>
                <ode/>
              </torsional>
            </friction>
            <bounce/>
          </surface>
          <max_contacts>10</max_contacts>
        </collision>
        <visual name='link_3_visual'>
          <pose>0 0 0.15 0 -0 0</pose>
          <geometry>
            <cylinder>
              <length>0.3</length>
              <radius>0.025</radius>
            </cylinder>
          </geometry>
          <material>
            <ambient>0.5 0.5 0.5 1</ambient>
            <diffuse>0.566667 0.566667 0.566667 1</diffuse>
            <specular>0.6 0.6 0.6 1</specular>
          </material>
        </visual>
        <self_collide>0</self_collide>
        <enable_wind>0</enable_wind>
        <kinematic>0</kinematic>
      </link>
      <joint name='joint_4' type='revolute'>
        <pose relative_to='link_3'>0 0 0.3 0 -0 0</pose>
        <parent>link_3</parent>
        <child>link_4</child>
        <axis>
          <xyz>0 0 1</xyz>
          <limit>
            <lower>-3.14159</lower>
            <upper>6.28318</upper>
            <effort>300</effort>
            <velocity>1</velocity>
          </limit>
          <dynamics>
            <spring_reference>0</spring_reference>
            <spring_stiffness>0</spring_stiffness>
          </dynamics>
        </axis>
      </joint>
      <link name='link_4'>
        <pose relative_to='joint_4'>0 0 0 0 -0 0</pose>
        <inertial>
          <pose>0 0 0.07502 0 -0 0</pose>
          <mass>1.001</mass>
          <inertia>
            <ixx>0.00208375</ixx>
            <ixy>0</ixy>
            <ixz>0</ixz>
            <iyy>0.00208375</iyy>
            <iyz>0</iyz>
            <izz>0.000416667</izz>
          </inertia>
        </inertial>
        <collision name='link_4_collision'>
          <pose>0 0 0.0125 0 -0 0</pose>
          <geometry>
            <box>
              <size>0.05 0.05 0.15</size>
            </box>
          </geometry>
          <surface>
            <contact>
              <ode/>
            </contact>
            <friction>
              <ode/>
              <torsional>
                <ode/>
              </torsional>
            </friction>
            <bounce/>
          </surface>
          <max_contacts>10</max_contacts>
        </collision>
        <collision name='link_4_fixed_joint_lump__gripper_frame_cp_collision_1'>
          <pose>0 0 0.095 0 -0 0</pose>
          <geometry>
            <box>
              <size>0.001 0.001 0.001</size>
            </box>
          </geometry>
          <max_contacts>10</max_contacts>
          <surface>
            <contact>
              <ode/>
            </contact>
            <bounce/>
            <friction>
              <torsional>
                <ode/>
              </torsional>
              <ode/>
            </friction>
          </surface>
        </collision>
        <visual name='link_4_visual'>
          <pose>0 0 0.0125 3.14159 1.57079 3.14159</pose>
          <geometry>
            <box>
              <size>0.05 0.05 0.15</size>
            </box>
          </geometry>
          <material>
            <ambient>0.5 0.5 0.5 1</ambient>
            <diffuse>0.566667 0.566667 0.566667 1</diffuse>
            <specular>0.6 0.6 0.6 1</specular>
          </material>
        </visual>
        <visual name='link_4_fixed_joint_lump__gripper_frame_cp_visual_1'>
          <pose>0 0 0.095 0 -0 0</pose>
          <geometry>
            <box>
              <size>0.001 0.001 0.001</size>
            </box>
          </geometry>
        </visual>
        <self_collide>0</self_collide>
        <enable_wind>0</enable_wind>
        <kinematic>0</kinematic>
      </link>
      <joint name='gripper_joint_1' type='prismatic'>
        <pose relative_to='link_4'>0 0 0.06 0 -0 0</pose>
        <parent>link_4</parent>
        <child>gripper_link_1</child>
        <axis>
          <xyz>1 0 0</xyz>
          <limit>
            <lower>0.01</lower>
            <upper>0.05</upper>
            <effort>100</effort>
            <velocity>1</velocity>
          </limit>
          <dynamics>
            <spring_reference>0</spring_reference>
            <spring_stiffness>0</spring_stiffness>
          </dynamics>
        </axis>
      </joint>
      <link name='gripper_link_1'>
        <pose relative_to='gripper_joint_1'>0 0 0 0 -0 0</pose>
        <inertial>
          <pose>0 0 0.035 0 -0 0</pose>
          <mass>0.2</mass>
          <inertia>
            <ixx>0.000108333</ixx>
            <ixy>0</ixy>
            <ixz>0</ixz>
            <iyy>0.000108333</iyy>
            <iyz>0</iyz>
            <izz>5.33333e-05</izz>
          </inertia>
        </inertial>
        <collision name='gripper_link_1_collision'>
          <pose>0 0 0.01 0 -0 0</pose>
          <geometry>
            <box>
              <size>0.04 0.04 0.07</size>
            </box>
          </geometry>
          <surface>
            <contact>
              <ode/>
            </contact>
            <friction>
              <ode/>
              <torsional>
                <ode/>
              </torsional>
            </friction>
            <bounce/>
          </surface>
          <max_contacts>10</max_contacts>
        </collision>
        <visual name='gripper_link_1_visual'>
          <pose>0 0 0.01 0 -0 0</pose>
          <geometry>
            <box>
              <size>0.02 0.04 0.07</size>
            </box>
          </geometry>
          <material>
            <ambient>0.5 0.5 0.5 1</ambient>
            <diffuse>0.566667 0.566667 0.566667 1</diffuse>
            <specular>0.6 0.6 0.6 1</specular>
          </material>
        </visual>
        <self_collide>0</self_collide>
        <enable_wind>0</enable_wind>
        <kinematic>0</kinematic>
      </link>
      <joint name='gripper_joint_2' type='prismatic'>
        <pose relative_to='link_4'>0 0 0.06 0 -0 0</pose>
        <parent>link_4</parent>
        <child>gripper_link_2</child>
        <axis>
          <xyz>1 0 0</xyz>
          <limit>
            <lower>-0.05</lower>
            <upper>-0.01</upper>
            <effort>100</effort>
            <velocity>1</velocity>
          </limit>
          <dynamics>
            <spring_reference>0</spring_reference>
            <spring_stiffness>0</spring_stiffness>
          </dynamics>
        </axis>
      </joint>
      <link name='gripper_link_2'>
        <pose relative_to='gripper_joint_2'>0 0 0 0 -0 0</pose>
        <inertial>
          <pose>0 0 0.035 0 -0 0</pose>
          <mass>0.2</mass>
          <inertia>
            <ixx>0.000108333</ixx>
            <ixy>0</ixy>
            <ixz>0</ixz>
            <iyy>0.000108333</iyy>
            <iyz>0</iyz>
            <izz>5.33333e-05</izz>
          </inertia>
        </inertial>
        <collision name='gripper_link_2_collision'>
          <pose>0 0 0.01 0 -0 0</pose>
          <geometry>
            <box>
              <size>0.04 0.04 0.07</size>
            </box>
          </geometry>
          <surface>
            <contact>
              <ode/>
            </contact>
            <friction>
              <ode/>
              <torsional>
                <ode/>
              </torsional>
            </friction>
            <bounce/>
          </surface>
          <max_contacts>10</max_contacts>
        </collision>
        <visual name='gripper_link_2_visual'>
          <pose>0 0 0.01 0 -0 0</pose>
          <geometry>
            <box>
              <size>0.02 0.04 0.07</size>
            </box>
          </geometry>
          <material>
            <ambient>0.5 0.5 0.5 1</ambient>
            <diffuse>0.566667 0.566667 0.566667 1</diffuse>
            <specular>0.6 0.6 0.6 1</specular>
          </material>
        </visual>
        <self_collide>0</self_collide>
        <enable_wind>0</enable_wind>
        <kinematic>0</kinematic>
      </link>
      <joint name='link_2_endjoint' type='fixed'>
        <pose relative_to='link_2'>-0.035 0 0.49 0 1.57079 0</pose>
        <parent>link_2</parent>
        <child>link_2_endlink</child>
        <axis>
          <dynamics>
            <spring_reference>0</spring_reference>
            <spring_stiffness>0</spring_stiffness>
          </dynamics>
          <xyz>0 0 1</xyz>
          <limit>
            <lower>-1e+16</lower>
            <upper>1e+16</upper>
          </limit>
        </axis>
        <physics>
          <ode>
            <limit>
              <cfm>0</cfm>
              <erp>0.2</erp>
            </limit>
          </ode>
        </physics>
      </joint>
      <link name='link_2_endlink'>
        <pose relative_to='link_2_endjoint'>0 0 0 0 -0 0</pose>
        <inertial>
          <pose>0 0 0.06 0 -0 0</pose>
          <mass>1</mass>
          <inertia>
            <ixx>0.00160833</ixx>
            <ixy>0</ixy>
            <ixz>0</ixz>
            <iyy>0.00160833</iyy>
            <iyz>0</iyz>
            <izz>0.000816667</izz>
          </inertia>
        </inertial>
        <collision name='link_2_endlink_collision'>
          <pose>0 0 0.06 0 -0 0</pose>
          <geometry>
            <cylinder>
              <length>0.12</length>
              <radius>0.0385</radius>
            </cylinder>
          </geometry>
          <surface>
            <contact>
              <ode/>
            </contact>
            <friction>
              <ode/>
              <torsional>
                <ode/>
              </torsional>
            </friction>
            <bounce/>
          </surface>
          <max_contacts>10</max_contacts>
        </collision>
        <visual name='link_2_endlink_visual'>
          <pose>0 0 0.06 0 -0 0</pose>
          <geometry>
            <cylinder>
              <length>0.12</length>
              <radius>0.0385</radius>
            </cylinder>
          </geometry>
          <material>
            <ambient>0.589 0.793 1 1</ambient>
            <diffuse>0.566667 0.566667 0.566667 1</diffuse>
            <specular>0.6 0.6 0.6 1</specular>
          </material>
        </visual>
        <self_collide>0</self_collide>
        <enable_wind>0</enable_wind>
        <kinematic>0</kinematic>
      </link>
      <joint name='link_1_endjoint' type='fixed'>
        <pose relative_to='link_1'>-0.05 0 0.39 0 1.57079 0</pose>
        <parent>link_1</parent>
        <child>link_1_endlink</child>
        <axis>
          <dynamics>
            <spring_reference>0</spring_reference>
            <spring_stiffness>0</spring_stiffness>
          </dynamics>
          <xyz>0 0 1</xyz>
          <limit>
            <lower>-1e+16</lower>
            <upper>1e+16</upper>
          </limit>
        </axis>
        <physics>
          <ode>
            <limit>
              <cfm>0</cfm>
              <erp>0.2</erp>
            </limit>
          </ode>
        </physics>
      </joint>
      <link name='link_1_endlink'>
        <pose relative_to='link_1_endjoint'>0 0 0 0 -0 0</pose>
        <inertial>
          <pose>0 0 0.085 0 -0 0</pose>
          <mass>1.66667</mass>
          <inertia>
            <ixx>0.00540278</ixx>
            <ixy>0</ixy>
            <ixz>0</ixz>
            <iyy>0.00540278</iyy>
            <iyz>0</iyz>
            <izz>0.00277778</izz>
          </inertia>
        </inertial>
        <collision name='link_1_endlink_collision'>
          <pose>0 0 0.085 0 -0 0</pose>
          <geometry>
            <cylinder>
              <length>0.17</length>
              <radius>0.055</radius>
            </cylinder>
          </geometry>
          <surface>
            <contact>
              <ode/>
            </contact>
            <friction>
              <ode/>
              <torsional>
                <ode/>
              </torsional>
            </friction>
            <bounce/>
          </surface>
          <max_contacts>10</max_contacts>
        </collision>
        <visual name='link_1_endlink_visual'>
          <pose>0 0 0.085 0 -0 0</pose>
          <geometry>
            <cylinder>
              <length>0.17</length>
              <radius>0.055</radius>
            </cylinder>
          </geometry>
          <material>
            <ambient>0.589 0.793 1 1</ambient>
            <diffuse>0.566667 0.566667 0.566667 1</diffuse>
            <specular>0.6 0.6 0.6 1</specular>
          </material>
        </visual>
        <self_collide>0</self_collide>
        <enable_wind>0</enable_wind>
        <kinematic>0</kinematic>
      </link>
      <static>0</static>
      <plugin name='gazebo_ros2_control' filename='libgazebo_ros2_control.so'>
        <parameters>/home/lou/ROS_workspaces/install/my_bot/share/my_bot/config/joint_position_controller.yaml</parameters>
      </plugin>
      <pose>0 0 0 0 -0 0</pose>
    </model>
    <model name='unit_sphere'>
      <link name='link'>
        <inertial>
          <mass>1</mass>
          <inertia>
            <ixx>0.1</ixx>
            <ixy>0</ixy>
            <ixz>0</ixz>
            <iyy>0.1</iyy>
            <iyz>0</iyz>
            <izz>0.1</izz>
          </inertia>
          <pose>0 0 0 0 -0 0</pose>
        </inertial>
        <self_collide>0</self_collide>
        <enable_wind>0</enable_wind>
        <kinematic>0</kinematic>
        <pose>-0.117609 -1.06567 0 0 -0 0</pose>
        <gravity>1</gravity>
        <visual name='visual'>
          <geometry>
            <sphere>
              <radius>0.2</radius>
            </sphere>
          </geometry>
          <material>
            <script>
              <name>Gazebo/Grey</name>
              <uri>file://media/materials/scripts/gazebo.material</uri>
            </script>
            <shader type='pixel'>
              <normal_map>__default__</normal_map>
            </shader>
            <ambient>0.3 0.3 0.3 1</ambient>
            <diffuse>0.7 0.7 0.7 1</diffuse>
            <specular>0.01 0.01 0.01 1</specular>
            <emissive>0 0 0 1</emissive>
          </material>
          <pose>0 0 0 0 -0 0</pose>
          <transparency>0</transparency>
          <cast_shadows>1</cast_shadows>
        </visual>
        <collision name='collision'>
          <laser_retro>0</laser_retro>
          <max_contacts>10</max_contacts>
          <pose>0 0 0 0 -0 0</pose>
          <geometry>
            <sphere>
              <radius>0.5</radius>
            </sphere>
          </geometry>
          <surface>
            <friction>
              <ode>
                <mu>1</mu>
                <mu2>1</mu2>
                <fdir1>0 0 0</fdir1>
                <slip1>0</slip1>
                <slip2>0</slip2>
              </ode>
              <torsional>
                <coefficient>1</coefficient>
                <patch_radius>0</patch_radius>
                <surface_radius>0</surface_radius>
                <use_patch_radius>1</use_patch_radius>
                <ode>
                  <slip>0</slip>
                </ode>
              </torsional>
            </friction>
            <bounce>
              <restitution_coefficient>0</restitution_coefficient>
              <threshold>1e+06</threshold>
            </bounce>
            <contact>
              <collide_without_contact>0</collide_without_contact>
              <collide_without_contact_bitmask>1</collide_without_contact_bitmask>
              <collide_bitmask>1</collide_bitmask>
              <ode>
                <soft_cfm>0</soft_cfm>
                <soft_erp>0.2</soft_erp>
                <kp>1e+13</kp>
                <kd>1</kd>
                <max_vel>0.01</max_vel>
                <min_depth>0</min_depth>
              </ode>
              <bullet>
                <split_impulse>1</split_impulse>
                <split_impulse_penetration_threshold>-0.01</split_impulse_penetration_threshold>
                <soft_cfm>0</soft_cfm>
                <soft_erp>0.2</soft_erp>
                <kp>1e+13</kp>
                <kd>1</kd>
              </bullet>
            </contact>
          </surface>
        </collision>
      </link>
      <static>0</static>
      <allow_auto_disable>1</allow_auto_disable>
      <pose>0.674069 0.317835 0.5 0 -0 0</pose>
    </model>
    <model name='unit_sphere_0'>
      <link name='link'>
        <inertial>
          <mass>1</mass>
          <inertia>
            <ixx>0.1</ixx>
            <ixy>0</ixy>
            <ixz>0</ixz>
            <iyy>0.1</iyy>
            <iyz>0</iyz>
            <izz>0.1</izz>
          </inertia>
          <pose>0 0 0 0 -0 0</pose>
        </inertial>
        <self_collide>0</self_collide>
        <enable_wind>0</enable_wind>
        <kinematic>0</kinematic>
        <pose>-0.270322 -0.072271 -0.099175 0 -0 0</pose>
        <gravity>1</gravity>
        <visual name='visual'>
          <geometry>
            <sphere>
              <radius>0.2</radius>
            </sphere>
          </geometry>
          <material>
            <script>
              <name>Gazebo/Grey</name>
              <uri>file://media/materials/scripts/gazebo.material</uri>
            </script>
            <shader type='pixel'>
              <normal_map>__default__</normal_map>
            </shader>
            <ambient>0.3 0.3 0.3 1</ambient>
            <diffuse>0.7 0.7 0.7 1</diffuse>
            <specular>0.01 0.01 0.01 1</specular>
            <emissive>0 0 0 1</emissive>
          </material>
          <pose>0 0 0 0 -0 0</pose>
          <transparency>0</transparency>
          <cast_shadows>1</cast_shadows>
        </visual>
        <collision name='collision'>
          <laser_retro>0</laser_retro>
          <max_contacts>10</max_contacts>
          <pose>0 0 0 0 -0 0</pose>
          <geometry>
            <sphere>
              <radius>0.2</radius>
            </sphere>
          </geometry>
          <surface>
            <friction>
              <ode>
                <mu>1</mu>
                <mu2>1</mu2>
                <fdir1>0 0 0</fdir1>
                <slip1>0</slip1>
                <slip2>0</slip2>
              </ode>
              <torsional>
                <coefficient>1</coefficient>
                <patch_radius>0</patch_radius>
                <surface_radius>0</surface_radius>
                <use_patch_radius>1</use_patch_radius>
                <ode>
                  <slip>0</slip>
                </ode>
              </torsional>
            </friction>
            <bounce>
              <restitution_coefficient>0</restitution_coefficient>
              <threshold>1e+06</threshold>
            </bounce>
            <contact>
              <collide_without_contact>0</collide_without_contact>
              <collide_without_contact_bitmask>1</collide_without_contact_bitmask>
              <collide_bitmask>1</collide_bitmask>
              <ode>
                <soft_cfm>0</soft_cfm>
                <soft_erp>0.2</soft_erp>
                <kp>1e+13</kp>
                <kd>1</kd>
                <max_vel>0.01</max_vel>
                <min_depth>0</min_depth>
              </ode>
              <bullet>
                <split_impulse>1</split_impulse>
                <split_impulse_penetration_threshold>-0.01</split_impulse_penetration_threshold>
                <soft_cfm>0</soft_cfm>
                <soft_erp>0.2</soft_erp>
                <kp>1e+13</kp>
                <kd>1</kd>
              </bullet>
            </contact>
          </surface>
        </collision>
      </link>
      <static>0</static>
      <allow_auto_disable>1</allow_auto_disable>
      <pose>0.872484 -0.532161 0.5 0 -0 0</pose>
    </model>
  </world>
</sdf>
